<?xml version="1.0" ?>
<robot name="gbot" xmlns:xacro="http://www.ros.org/wiki/xacro">

<xacro:include filename="$(find gbot_description)/urdf/materials.xacro" />
<xacro:include filename="$(find gbot_description)/urdf/gbot.trans" />
<xacro:include filename="$(find gbot_description)/urdf/gbot.gazebo" />
<link name="base_link">
  <inertial>
    <origin xyz="-9.393933552665679e-07 -2.165965709152816e-07 0.17194048530369713" rpy="0 0 0"/>
    <mass value="72.20766900922584"/>
    <inertia ixx="1.653982" iyy="2.747069" izz="4.052749" ixy="-2e-06" iyz="0.0" ixz="1e-06"/>
  </inertial>
  <visual>
    <origin xyz="0 0 0" rpy="0 0 0"/>
    <geometry>
      <mesh filename="package://gbot_description/meshes/base_link.stl" scale="0.001 0.001 0.001"/>
    </geometry>
    <material name="silver"/>
  </visual>
  <collision>
    <origin xyz="0 0 0" rpy="0 0 0"/>
    <geometry>
      <mesh filename="package://gbot_description/meshes/base_link.stl" scale="0.001 0.001 0.001"/>
    </geometry>
  </collision>
</link>

<link name="lidar_1">
  <inertial>
    <origin xyz="3.953623681769e-12 5.657535542014275e-12 0.014918354451196603" rpy="0 0 0"/>
    <mass value="0.5902873902138039"/>
    <inertia ixx="0.000572" iyy="0.000572" izz="0.001057" ixy="-0.0" iyz="-0.0" ixz="-0.0"/>
  </inertial>
  <visual>
    <origin xyz="0.0 -0.0 -0.32758" rpy="0 0 0"/>
    <geometry>
      <mesh filename="package://gbot_description/meshes/lidar_1.stl" scale="0.001 0.001 0.001"/>
    </geometry>
    <material name="silver"/>
  </visual>
  <collision>
    <origin xyz="0.0 -0.0 -0.32758" rpy="0 0 0"/>
    <geometry>
      <mesh filename="package://gbot_description/meshes/lidar_1.stl" scale="0.001 0.001 0.001"/>
    </geometry>
  </collision>
</link>

<link name="_flw_1">
  <inertial>
    <origin xyz="-1.0581438099149798e-05 -0.01295672824963795 4.5099003603832344e-07" rpy="0 0 0"/>
    <mass value="7.588715528859276"/>
    <inertia ixx="0.050298" iyy="0.089426" izz="0.049879" ixy="-0.0" iyz="-2e-06" ixz="1e-06"/>
  </inertial>
  <visual>
    <origin xyz="-0.175 -0.33 -0.15508" rpy="0 0 0"/>
    <geometry>
      <mesh filename="package://gbot_description/meshes/_flw_1.stl" scale="0.001 0.001 0.001"/>
    </geometry>
    <material name="silver"/>
  </visual>
  <collision>
    <origin xyz="-0.175 -0.33 -0.15508" rpy="0 0 0"/>
    <geometry>
      <mesh filename="package://gbot_description/meshes/_flw_1.stl" scale="0.001 0.001 0.001"/>
    </geometry>
  </collision>
</link>

<link name="frw_1">
  <inertial>
    <origin xyz="1.059119288390753e-05 0.012956731123297482 -4.5677149326794897e-07" rpy="0 0 0"/>
    <mass value="7.588703477399117"/>
    <inertia ixx="0.050298" iyy="0.089426" izz="0.049879" ixy="-0.0" iyz="-2e-06" ixz="0.0"/>
  </inertial>
  <visual>
    <origin xyz="-0.175 0.33 -0.15508" rpy="0 0 0"/>
    <geometry>
      <mesh filename="package://gbot_description/meshes/frw_1.stl" scale="0.001 0.001 0.001"/>
    </geometry>
    <material name="silver"/>
  </visual>
  <collision>
    <origin xyz="-0.175 0.33 -0.15508" rpy="0 0 0"/>
    <geometry>
      <mesh filename="package://gbot_description/meshes/frw_1.stl" scale="0.001 0.001 0.001"/>
    </geometry>
  </collision>
</link>

<link name="blw_1">
  <inertial>
    <origin xyz="1.0585605095397854e-05 -0.012956724638741701 3.904316508707151e-07" rpy="0 0 0"/>
    <mass value="7.588704309780978"/>
    <inertia ixx="0.050298" iyy="0.089426" izz="0.049879" ixy="0.0" iyz="-2e-06" ixz="-1e-06"/>
  </inertial>
  <visual>
    <origin xyz="0.175 -0.33 -0.15508" rpy="0 0 0"/>
    <geometry>
      <mesh filename="package://gbot_description/meshes/blw_1.stl" scale="0.001 0.001 0.001"/>
    </geometry>
    <material name="silver"/>
  </visual>
  <collision>
    <origin xyz="0.175 -0.33 -0.15508" rpy="0 0 0"/>
    <geometry>
      <mesh filename="package://gbot_description/meshes/blw_1.stl" scale="0.001 0.001 0.001"/>
    </geometry>
  </collision>
</link>

<link name="brw_1">
  <inertial>
    <origin xyz="1.058567770281793e-05 0.0129567311426807 3.8497833163009254e-07" rpy="0 0 0"/>
    <mass value="7.588715257119841"/>
    <inertia ixx="0.050298" iyy="0.089426" izz="0.049879" ixy="-0.0" iyz="2e-06" ixz="-0.0"/>
  </inertial>
  <visual>
    <origin xyz="0.175 0.33 -0.15508" rpy="0 0 0"/>
    <geometry>
      <mesh filename="package://gbot_description/meshes/brw_1.stl" scale="0.001 0.001 0.001"/>
    </geometry>
    <material name="silver"/>
  </visual>
  <collision>
    <origin xyz="0.175 0.33 -0.15508" rpy="0 0 0"/>
    <geometry>
      <mesh filename="package://gbot_description/meshes/brw_1.stl" scale="0.001 0.001 0.001"/>
    </geometry>
  </collision>
</link>

<joint name="l_j" type="fixed">
  <origin xyz="0.0 0.0 0.32758" rpy="0 0 0"/>
  <parent link="base_link"/>
  <child link="lidar_1"/>
</joint>

<joint name="flw_j" type="continuous">
  <origin xyz="0.175 0.33 0.15508" rpy="0 0 0"/>
  <parent link="base_link"/>
  <child link="_flw_1"/>
  <axis xyz="-0.0 1.0 0.0"/>
</joint>

<joint name=" frw_j" type="continuous">
  <origin xyz="0.175 -0.33 0.15508" rpy="0 0 0"/>
  <parent link="base_link"/>
  <child link="frw_1"/>
  <axis xyz="-0.0 1.0 0.0"/>
</joint>

<joint name="blw_j" type="continuous">
  <origin xyz="-0.175 0.33 0.15508" rpy="0 0 0"/>
  <parent link="base_link"/>
  <child link="blw_1"/>
  <axis xyz="0.0 1.0 0.0"/>
</joint>

<joint name="brw_j" type="continuous">
  <origin xyz="-0.175 -0.33 0.15508" rpy="0 0 0"/>
  <parent link="base_link"/>
  <child link="brw_1"/>
  <axis xyz="0.0 1.0 0.0"/>
</joint>

</robot>
